<mujoco model="ballbot">
  <compiler meshdir="stl_files" />
  <option timestep="0.002" />

  <asset>
    <mesh name="base_mesh" file="tower.stl" scale="0.001 0.001 0.001"/> <!-- rescaling because freecad uses mm but mujoco uses meters-->
    <mesh name="omni_mesh_0" file="omniwheel_0.stl" scale="0.001 0.001 0.001"/> <!-- rescaling because freecad uses mm but mujoco uses meters-->
    <mesh name="omni_mesh_1" file="omniwheel_1.stl" scale="0.001 0.001 0.001"/> <!-- rescaling because freecad uses mm but mujoco uses meters-->
    <mesh name="omni_mesh_2" file="omniwheel_2.stl" scale="0.001 0.001 0.001"/> <!-- rescaling because freecad uses mm but mujoco uses meters-->
    <texture name="grid" type="2d" builtin="checker" rgb1=".1 .2 .3" rgb2=".2 .3 .4" width="300" height="300"/>
    <material name="grid" texture="grid" texrepeat="8 8" reflectance=".2"/>
  </asset>


  <worldbody>

    <light name="top" pos="0 0 1.0"/>
    <geom name="ground" type="plane" size="5 5 0.1" pos="0 0 0" rgba="0.8 0.8 0.8 1" material="grid"/>
    <!-- Base body with a free joint -->
    <body name="base" pos="0 0 0.5">
      <!--<freejoint />-->
      <geom type="mesh" mesh="base_mesh" rgba="0.0 0.5 0.0 0.5"/>

      <body name="wheel_0" pos="0 0 -0.001" euler="0 0 0">
        <geom type="mesh" mesh="omni_mesh_0" />
        <!--axis orientation from feedcad's python api, pos offset set manually-->
        <joint name="wheel_joint_0" type="hinge" axis="-0.15316554764123935 -0.6903189805903613 -0.7071067953657663" pos="0 0 0.0293" damping="0.1" armature="0.005"/>
      </body>

      <body name="wheel_1" pos="0 0 -0.001" euler="0 0 0">
        <geom type="mesh" mesh="omni_mesh_1" />
        <!--axis orientation from feedcad's python api, pos offset set manually-->
        <joint name="wheel_joint_1" type="hinge" axis="0.6741579351174821 0.2133331726359635 -0.7071068066220314" pos="0 0 0.0293" damping="0.1" armature="0.005"/>
      </body>

      <body name="wheel_2" pos="0 0 -0.001" euler="0 0 0">
        <geom type="mesh" mesh="omni_mesh_2" />
        <!--axis orientation from feedcad's python api, pos offset set manually-->
        <joint name="wheel_joint_2" type="hinge" axis="-0.5212219425699983 0.47783642277253024 -0.7071068092272265" pos="0 0 0.0293" damping="0.1" armature="0.005"/>
      </body>

    </body>
  </worldbody>

  <actuator>
    <velocity name="motor_0" joint="wheel_joint_0" ctrlrange="-10 10" kv="0.5"/>
    <velocity name="motor_1" joint="wheel_joint_1" ctrlrange="-10 10" kv="0.5"/>
    <velocity name="motor_2" joint="wheel_joint_2" ctrlrange="-10 10" kv="0.5"/>
  </actuator>

</mujoco>

