<mujoco model="ballbot">
  <compiler meshdir="stl_files" texturedir="textures" /> <!--path is relative to the xml file-->
  <option timestep="0.001" />

  <asset>
    <mesh name="base_mesh" file="tower.stl" scale="0.001 0.001 0.001"/> <!-- rescaling because freecad uses mm but mujoco uses meters-->
    <mesh name="omni_mesh_0" file="omniwheel_0.stl" scale="0.001 0.001 0.001"/> <!-- rescaling because freecad uses mm but mujoco uses meters-->
    <mesh name="omni_mesh_1" file="omniwheel_1.stl" scale="0.001 0.001 0.001"/> <!-- rescaling because freecad uses mm but mujoco uses meters-->
    <mesh name="omni_mesh_2" file="omniwheel_2.stl" scale="0.001 0.001 0.001"/> <!-- rescaling because freecad uses mm but mujoco uses meters-->
    <texture name="grid" type="2d" builtin="checker" rgb1=".1 .2 .3" rgb2=".2 .3 .4" width="300" height="300"/>
    <material name="grid" texture="grid" texrepeat="8 8" reflectance=".2"/>
    <texture name="basketball_tex" type="2d" file="basketball_texture.png"/>
    <material name="basketball_mat" texture="basketball_tex" shininess="0.2"/>
  </asset>


  <worldbody>

    <light name="top" pos="0 0 1.0"/>
    <geom name="ground" type="plane" size="5 5 0.1" pos="0 0 0" rgba="0.8 0.8 0.8 1" material="grid"/>
    <!-- Base body with a free joint -->
    <body name="base" pos="0 0 0.36">
      <!--<freejoint />-->
      <!-- density is in kg/m^3. I'll trust mujoco's volume computation, and since the tower is around 1.7kg (with electronics, wheels and cover), I'm fixing the density such that the value  -->
      <!-- that is returned by model.body("base").mass is ~1.55. Wheel mass will be added independently. Not specifying intertia matrix since Mujoco's estimate is probably better than mine -->
      <geom type="mesh" mesh="base_mesh" rgba="0.0 0.5 0.0 0.5" density="83.6"/>

      <body name="wheel_0" pos="0 0 -0.001" euler="0 0 0">
        <!--each omniwheel is about 0.054kg on the real robot-->
        <geom type="mesh" mesh="omni_mesh_0" density="620.0"/>
        <!--axis orientation from feedcad's python api, pos offset set manually-->
        <joint name="wheel_joint_0" type="hinge" axis="-0.15316554764123935 -0.6903189805903613 -0.7071067953657663" pos="0 0 0.0293" damping="0.1" armature="0.005"/>
      </body>

    </body>
    
    <body name="ball" pos="0 0.0 0.15">
      <!--<freejoint />-->
      <geom name="green_sphere" size=".14" rgba="1 1 1 0.1" density="100"   material="basketball_mat" friction="0.6 0.6 0.005" />
      <joint name="basket_joint" type="hinge" axis="0 0 1" pos="0 0 0"/>
    </body>
  </worldbody>

  <actuator>
    <velocity name="motor_0" joint="wheel_joint_0" ctrlrange="-50 50" kv="0.5"/>
    <velocity name="basket_motor" joint="basket_joint" ctrlrange="-50 50"/>
  </actuator>

</mujoco>

